在 C++ 中，`catch` 块中再次抛出异常是一种处理异常的方式，通常用于以下几种情况：

### 1. **重新抛出异常**
   在 `catch` 块中捕获异常后，可能需要对异常进行一些处理（如日志记录、资源清理等），但不想在当前层级完全处理该异常，而是希望将其传递给更高层级的调用者处理。这时可以在 `catch` 块中使用 `throw;` 重新抛出异常。

   ```cpp
   try {
       // 可能抛出异常的代码
   } catch (const std::exception& e) {
       // 记录日志或执行其他操作
       std::cerr << "Exception caught: " << e.what() << std::endl;
       
       // 重新抛出异常
       throw;
   }
   ```

   **适用场景**：
   - 当前层级无法完全处理异常，需要让调用者进一步处理。
   - 需要在异常传递过程中记录日志或执行其他操作。

---

### 2. **捕获并转换异常**
   有时在 `catch` 块中捕获一个异常后，希望将其转换为另一种类型的异常并抛出。这种操作通常用于统一异常类型或提供更具体的异常信息。

   ```cpp
   try {
       // 可能抛出异常的代码
   } catch (const std::runtime_error& e) {
       // 转换为自定义异常
       throw MyCustomException("Runtime error occurred: " + std::string(e.what()));
   }
   ```

   **适用场景**：
   - 需要将底层异常转换为更高层次的抽象异常。
   - 需要为异常添加更多上下文信息。

---

### 3. **部分处理异常**
   在 `catch` 块中捕获异常后，可能只需要处理部分情况，而其他情况仍需抛出异常。

   ```cpp
   try {
       // 可能抛出异常的代码
   } catch (const std::out_of_range& e) {
       // 处理特定异常
       std::cerr << "Out of range error: " << e.what() << std::endl;
   } catch (const std::exception& e) {
       // 处理其他异常并重新抛出
       std::cerr << "Unknown exception: " << e.what() << std::endl;
       throw;
   }
   ```

   **适用场景**：
   - 需要针对特定异常类型进行特殊处理，而其他异常仍需传递。

---

### 4. **异常链（Exception Chaining）**
   在某些情况下，可能需要将原始异常与新抛出的异常关联起来，形成异常链。C++ 标准库本身不支持直接的异常链，但可以通过自定义异常类实现。

   ```cpp
   class MyException : public std::exception {
       std::string message;
       std::exception_ptr originalException;
   public:
       MyException(const std::string& msg, std::exception_ptr original)
           : message(msg), originalException(original) {}

       const char* what() const noexcept override {
           return message.c_str();
       }

       std::exception_ptr getOriginalException() const {
           return originalException;
       }
   };

   try {
       try {
           // 可能抛出异常的代码
       } catch (const std::exception& e) {
           // 捕获并包装原始异常
           throw MyException("Wrapped exception", std::current_exception());
       }
   } catch (const MyException& e) {
       std::cerr << "Caught MyException: " << e.what() << std::endl;
       // 可以进一步处理原始异常
       if (auto original = e.getOriginalException()) {
           try {
               std::rethrow_exception(original);
           } catch (const std::exception& e) {
               std::cerr << "Original exception: " << e.what() << std::endl;
           }
       }
   }
   ```

   **适用场景**：
   - 需要保留原始异常的上下文信息。
   - 在多层异常处理中，需要追踪异常的来源。

---

### 总结
在 `catch` 块中重新抛出异常或转换异常是一种灵活的处理方式，适用于以下场景：
1. 需要将异常传递给更高层级的调用者。
2. 需要将异常转换为另一种类型。
3. 需要部分处理异常，同时保留异常的传递能力。
4. 需要实现异常链以保留原始异常的上下文。

需要注意的是，过度使用异常重新抛出可能会导致代码难以维护，因此应谨慎使用，并确保异常处理的逻辑清晰。