
"smart_sources:C++/我的探索/learn_from_zeck/C++base/异常的再抛出.md": {"path":"C++/我的探索/learn_from_zeck/C++base/异常的再抛出.md","last_embed":{"hash":null},"embeddings":{},"last_read":{"hash":"5c6258c5eeecedb89991625ca3f6b6b27fa0cf45f74d7bd44e3160eaceb4a8a4","at":1736915163238},"class_name":"SmartSource","outlinks":[],"last_import":{"mtime":1736673064000,"size":4156,"at":1736915163238,"hash":"5c6258c5eeecedb89991625ca3f6b6b27fa0cf45f74d7bd44e3160eaceb4a8a4"},"blocks":{"#":[1,2],"###1. **重新抛出异常**":[3,41],"###1. **重新抛出异常**#{1}":[4,41],"#---frontmatter---":[22,40],"###3. **部分处理异常**":[42,62],"###3. **部分处理异常**#{1}":[43,62],"###4. **异常链（Exception Chaining）**":[63,108],"###4. **异常链（Exception Chaining）**#{1}":[64,108],"###总结":[109,116],"###总结#{1}":[110,116]}},